Traceback (most recent call last):
  File "/usr/share/miniconda/lib/python3.9/site-packages/jupyter_cache/executors/utils.py", line 51, in single_nb_execution
    executenb(
  File "/usr/share/miniconda/lib/python3.9/site-packages/nbclient/client.py", line 1204, in execute
    return NotebookClient(nb=nb, resources=resources, km=km, **kwargs).execute()
  File "/usr/share/miniconda/lib/python3.9/site-packages/nbclient/util.py", line 84, in wrapped
    return just_run(coro(*args, **kwargs))
  File "/usr/share/miniconda/lib/python3.9/site-packages/nbclient/util.py", line 62, in just_run
    return loop.run_until_complete(coro)
  File "/usr/share/miniconda/lib/python3.9/asyncio/base_events.py", line 642, in run_until_complete
    return future.result()
  File "/usr/share/miniconda/lib/python3.9/site-packages/nbclient/client.py", line 663, in async_execute
    await self.async_execute_cell(
  File "/usr/share/miniconda/lib/python3.9/site-packages/nbclient/client.py", line 965, in async_execute_cell
    await self._check_raise_for_error(cell, cell_index, exec_reply)
  File "/usr/share/miniconda/lib/python3.9/site-packages/nbclient/client.py", line 862, in _check_raise_for_error
    raise CellExecutionError.from_cell_and_msg(cell, exec_reply_content)
nbclient.exceptions.CellExecutionError: An error occurred while executing the following cell:
------------------
import numpy as np
from scipy import stats, ndimage, interpolate
from astropy import stats as astrostats
from photutils import (
    datasets,  # For making simulated data
    Background2D,  # For estimating the background
    MedianBackground, BiweightLocationBackground, SExtractorBackground,
    BkgIDWInterpolator, BkgZoomInterpolator,  # For interpolating background
    make_source_mask)
from photutils.utils import ShepardIDWInterpolator as idw
from astropy.table import Table
from astropy.convolution import (
    convolve, Box2DKernel, Tophat2DKernel,
    Ring2DKernel, Gaussian2DKernel)
from scipy.ndimage.filters import median_filter
from astropy.modeling import models, fitting
from astropy.nddata.utils import block_reduce
------------------

[0;31m---------------------------------------------------------------------------[0m
[0;31mImportError[0m                               Traceback (most recent call last)
Input [0;32mIn [2][0m, in [0;36m<cell line: 17>[0;34m()[0m
[1;32m     15[0m [38;5;28;01mfrom[39;00m [38;5;21;01mscipy[39;00m[38;5;21;01m.[39;00m[38;5;21;01mndimage[39;00m[38;5;21;01m.[39;00m[38;5;21;01mfilters[39;00m [38;5;28;01mimport[39;00m median_filter
[1;32m     16[0m [38;5;28;01mfrom[39;00m [38;5;21;01mastropy[39;00m[38;5;21;01m.[39;00m[38;5;21;01mmodeling[39;00m [38;5;28;01mimport[39;00m models, fitting
[0;32m---> 17[0m [38;5;28;01mfrom[39;00m [38;5;21;01mastropy[39;00m[38;5;21;01m.[39;00m[38;5;21;01mnddata[39;00m[38;5;21;01m.[39;00m[38;5;21;01mutils[39;00m [38;5;28;01mimport[39;00m block_reduce

[0;31mImportError[0m: cannot import name 'block_reduce' from 'astropy.nddata.utils' (/usr/share/miniconda/lib/python3.9/site-packages/astropy/nddata/utils.py)
ImportError: cannot import name 'block_reduce' from 'astropy.nddata.utils' (/usr/share/miniconda/lib/python3.9/site-packages/astropy/nddata/utils.py)

