Traceback (most recent call last):
  File "/usr/share/miniconda/lib/python3.9/site-packages/jupyter_cache/executors/utils.py", line 51, in single_nb_execution
    executenb(
  File "/usr/share/miniconda/lib/python3.9/site-packages/nbclient/client.py", line 1204, in execute
    return NotebookClient(nb=nb, resources=resources, km=km, **kwargs).execute()
  File "/usr/share/miniconda/lib/python3.9/site-packages/nbclient/util.py", line 84, in wrapped
    return just_run(coro(*args, **kwargs))
  File "/usr/share/miniconda/lib/python3.9/site-packages/nbclient/util.py", line 62, in just_run
    return loop.run_until_complete(coro)
  File "/usr/share/miniconda/lib/python3.9/asyncio/base_events.py", line 642, in run_until_complete
    return future.result()
  File "/usr/share/miniconda/lib/python3.9/site-packages/nbclient/client.py", line 663, in async_execute
    await self.async_execute_cell(
  File "/usr/share/miniconda/lib/python3.9/site-packages/nbclient/client.py", line 965, in async_execute_cell
    await self._check_raise_for_error(cell, cell_index, exec_reply)
  File "/usr/share/miniconda/lib/python3.9/site-packages/nbclient/client.py", line 862, in _check_raise_for_error
    raise CellExecutionError.from_cell_and_msg(cell, exec_reply_content)
nbclient.exceptions.CellExecutionError: An error occurred while executing the following cell:
------------------
import os

import numpy as np

from astropy.convolution import Gaussian2DKernel
from astropy.io import fits
from astropy.stats import gaussian_fwhm_to_sigma
from astropy.table import QTable
import astropy.units as u
from astropy.visualization import make_lupton_rgb, SqrtStretch, ImageNormalize, simple_norm
import astropy.wcs as wcs

import photutils
print('photutils', photutils.__version__)
from photutils import Background2D, MedianBackground, detect_sources, deblend_sources, source_properties
from photutils.utils import calc_total_error
------------------

[0;31m---------------------------------------------------------------------------[0m
[0;31mImportError[0m                               Traceback (most recent call last)
Input [0;32mIn [1][0m, in [0;36m<cell line: 15>[0;34m()[0m
[1;32m     13[0m [38;5;28;01mimport[39;00m [38;5;21;01mphotutils[39;00m
[1;32m     14[0m [38;5;28mprint[39m([38;5;124m'[39m[38;5;124mphotutils[39m[38;5;124m'[39m, photutils[38;5;241m.[39m__version__)
[0;32m---> 15[0m [38;5;28;01mfrom[39;00m [38;5;21;01mphotutils[39;00m [38;5;28;01mimport[39;00m Background2D, MedianBackground, detect_sources, deblend_sources, source_properties
[1;32m     16[0m [38;5;28;01mfrom[39;00m [38;5;21;01mphotutils[39;00m[38;5;21;01m.[39;00m[38;5;21;01mutils[39;00m [38;5;28;01mimport[39;00m calc_total_error

[0;31mImportError[0m: cannot import name 'source_properties' from 'photutils' (/usr/share/miniconda/lib/python3.9/site-packages/photutils/__init__.py)
ImportError: cannot import name 'source_properties' from 'photutils' (/usr/share/miniconda/lib/python3.9/site-packages/photutils/__init__.py)

